Workbook

Sheet Information
A1: Flow_Rate | B1: Formation_Thickness | C1: Porosity | D1: Total_Compressibility | E1: FVF | F1: Viscosity | G1: Wellbore_Radius
A2: 0.550395 | B2: 26.248 | C2: 0.02 | D2: 1.7e-06 | E2: 1 | F2: 0.6 | G2: 0.15748

Sheet Injection_Note
A1: INJECTION NOTES
A2: CONTRACT NO. EOGEPL/RG (EAST)-CBM-2001/1/MAPL-IFT/2021/01
A3: WELL No | B3: EDB-02 | D3: JOB-I | F3: START OF INJECTION | G3: 45475 | I3: 14:30:00 PM
A4: WELL DIAMETER | B4: 96 MM | F4: END OF INJECTION | G4: 45475 | I4: 0.10416667
A5: SEAM No | B5: RN-III | C5: 1018 | D5: To | E5: 1026 | F5: END OF FALL OFF
A6: IF TEST INTERVAL | C6: 1017.5 | D6: To | E6: 1026.7 | F6: TOTAL INJECTED WATER | K6: =E6-C6 -> 9.2 | O6: =1058.2-1048.1 -> 10.1 | P6: =O6*3.281 -> 33.1381
D7: FLOW METER | F7: WATER TANK PHYSICAL
A8: DATE | B8: TIME | C8: PRESSURE (PSI) | D8: FLOW RATE (LPM) | E8: TOTA WATER PUMPED (LITER) | F8: READING (LITER) | G8: TOTA WATER PUMPED (LITER) | H8: FLOW RATE (LPM) | I8: REMARK
A9: 45475 | B9: 0.99930556 | I9: Packer inflated @ 1885 PSI
A10: 45476 | B10: 0.0020833333 | I10: Went into injection mode (Total Stroke Length 55 cm) | N10: Time (hrs) | O10: Rate (LPM)
B11: 0.0069444444 | I11: Injection started | J11: =HOUR(B11) -> 0 | K11: =MINUTE(B11) -> 10 | L11: =SECOND(B11) -> 0 | M11: =J11+(K11/60)+(L11/3600) -> 0.16666667 | N11: =M11-$M$11 -> 0 | O11: 0 | P11: 0 | Q11: 0
B12: 0.010416667 | C12: 53 | F12: 1.62 | G12: =F12 -> 1.62 | H12: =F12/5 -> 0.324 | J12: =HOUR(B12) -> 0 | K12: =MINUTE(B12) -> 15 | L12: =SECOND(B12) -> 0 | M12: =J12+(K12/60)+(L12/3600) -> 0.25 | N12: =M12-$M$11 -> 0.083333333 | O12: =($G$13-$G$11)/($N$13-$N$11)/60 -> 0.243 | P12: =O12*(N12-N11)*60 -> 1.215 | Q12: =Q11+P12 -> 1.215
B13: 0.013888889 | C13: 86 | F13: 0.81 | G13: =G12+F13 -> 2.43 | H13: =F13/5 -> 0.162 | J13: =HOUR(B13) -> 0 | K13: =MINUTE(B13) -> 20 | L13: =SECOND(B13) -> 0 | M13: =J13+(K13/60)+(L13/3600) -> 0.33333333 | N13: =M13-$M$11 -> 0.16666667 | O13: =($G$13-$G$11)/($N$13-$N$11)/60 -> 0.243 | P13: =O13*(N13-N12)*60 -> 1.215 | Q13: =Q12+P13 -> 2.43
B14: 0.020833333 | C14: 114 | F14: 0 | G14: =G13+F14 -> 2.43 | H14: =F14/10 -> 0 | J14: =HOUR(B14) -> 0 | K14: =MINUTE(B14) -> 30 | L14: =SECOND(B14) -> 0 | M14: =J14+(K14/60)+(L14/3600) -> 0.5 | N14: =M14-$M$11 -> 0.33333333 | O14: =($G$42-$G$13)/($N$42-$N$12)/60 -> 0.038440678 | P14: =O14*(N14-N13)*60 -> 0.38440678 | Q14: =Q13+P14 -> 2.8144068
B15: 0.027777778 | C15: 134 | F15: 0 | G15: =G14+F15 -> 2.43 | H15: =F15/10 -> 0 | J15: =HOUR(B15) -> 0 | K15: =MINUTE(B15) -> 40 | L15: =SECOND(B15) -> 0 | M15: =J15+(K15/60)+(L15/3600) -> 0.66666667 | N15: =M15-$M$11 -> 0.5 | O15: =($G$42-$G$13)/($N$42-$N$12)/60 -> 0.038440678 | P15: =O15*(N15-N14)*60 -> 0.38440678 | Q15: =Q14+P15 -> 3.1988136
B16: 0.034722222 | C16: 191 | F16: 0.81 | G16: =G15+F16 -> 3.24 | H16: =F16/10 -> 0.081 | J16: =HOUR(B16) -> 0 | K16: =MINUTE(B16) -> 50 | L16: =SECOND(B16) -> 0 | M16: =J16+(K16/60)+(L16/3600) -> 0.83333333 | N16: =M16-$M$11 -> 0.66666667 | O16: =($G$42-$G$13)/($N$42-$N$12)/60 -> 0.038440678 | P16: =O16*(N16-N15)*60 -> 0.38440678 | Q16: =Q15+P16 -> 3.5832203 | T16: =PERCENTILE(H12:H80,0.5) -> 0.081 | U16: =T16*9.06 -> 0.73386
B17: 0.041666667 | C17: 239 | F17: 0 | G17: =G16+F17 -> 3.24 | H17: =F17/10 -> 0 | J17: =HOUR(B17) -> 1 | K17: =MINUTE(B17) -> 0 | L17: =SECOND(B17) -> 0 | M17: =J17+(K17/60)+(L17/3600) -> 1 | N17: =M17-$M$11 -> 0.83333333 | O17: =($G$42-$G$13)/($N$42-$N$12)/60 -> 0.038440678 | P17: =O17*(N17-N16)*60 -> 0.38440678 | Q17: =Q16+P17 -> 3.9676271
B18: 0.048611111 | C18: 286 | F18: 0.81 | G18: =G17+F18 -> 4.05 | H18: =F18/10 -> 0.081 | J18: =HOUR(B18) -> 1 | K18: =MINUTE(B18) -> 10 | L18: =SECOND(B18) -> 0 | M18: =J18+(K18/60)+(L18/3600) -> 1.1666667 | N18: =M18-$M$11 -> 1 | O18: =($G$42-$G$13)/($N$42-$N$12)/60 -> 0.038440678 | P18: =O18*(N18-N17)*60 -> 0.38440678 | Q18: =Q17+P18 -> 4.3520339
B19: 0.055555556 | C19: 332 | F19: 0.81 | G19: =G18+F19 -> 4.86 | H19: =F19/10 -> 0.081 | J19: =HOUR(B19) -> 1 | K19: =MINUTE(B19) -> 20 | L19: =SECOND(B19) -> 0 | M19: =J19+(K19/60)+(L19/3600) -> 1.3333333 | N19: =M19-$M$11 -> 1.1666667 | O19: =($G$42-$G$13)/($N$42-$N$12)/60 -> 0.038440678 | P19: =O19*(N19-N18)*60 -> 0.38440678 | Q19: =Q18+P19 -> 4.7364407
B20: 0.0625 | C20: 378 | F20: 0 | G20: =G19+F20 -> 4.86 | H20: =F20/10 -> 0 | J20: =HOUR(B20) -> 1 | K20: =MINUTE(B20) -> 30 | L20: =SECOND(B20) -> 0 | M20: =J20+(K20/60)+(L20/3600) -> 1.5 | N20: =M20-$M$11 -> 1.3333333 | O20: =($G$42-$G$13)/($N$42-$N$12)/60 -> 0.038440678 | P20: =O20*(N20-N19)*60 -> 0.38440678 | Q20: =Q19+P20 -> 5.1208475
B21: 0.069444444 | C21: 442 | F21: 0 | G21: =G20+F21 -> 4.86 | H21: =F21/10 -> 0 | J21: =HOUR(B21) -> 1 | K21: =MINUTE(B21) -> 40 | L21: =SECOND(B21) -> 0 | M21: =J21+(K21/60)+(L21/3600) -> 1.6666667 | N21: =M21-$M$11 -> 1.5 | O21: =($G$42-$G$13)/($N$42-$N$12)/60 -> 0.038440678 | P21: =O21*(N21-N20)*60 -> 0.38440678 | Q21: =Q20+P21 -> 5.5052542
B22: 0.076388889 | C22: 490 | F22: 0.81 | G22: =G21+F22 -> 5.67 | H22: =F22/10 -> 0.081 | J22: =HOUR(B22) -> 1 | K22: =MINUTE(B22) -> 50 | L22: =SECOND(B22) -> 0 | M22: =J22+(K22/60)+(L22/3600) -> 1.8333333 | N22: =M22-$M$11 -> 1.6666667 | O22: =($G$42-$G$13)/($N$42-$N$12)/60 -> 0.038440678 | P22: =O22*(N22-N21)*60 -> 0.38440678 | Q22: =Q21+P22 -> 5.889661 | U22: =1/0.1104078437 -> 9.0573275
B23: 0.083333333 | C23: 553 | F23: 0.81 | G23: =G22+F23 -> 6.48 | H23: =F23/10 -> 0.081 | J23: =HOUR(B23) -> 2 | K23: =MINUTE(B23) -> 0 | L23: =SECOND(B23) -> 0 | M23: =J23+(K23/60)+(L23/3600) -> 2 | N23: =M23-$M$11 -> 1.8333333 | O23: =($G$42-$G$13)/($N$42-$N$12)/60 -> 0.038440678 | P23: =O23*(N23-N22)*60 -> 0.38440678 | Q23: =Q22+P23 -> 6.2740678
B24: 0.090277778 | C24: 576 | F24: 0 | G24: =G23+F24 -> 6.48 | H24: =F24/10 -> 0 | J24: =HOUR(B24) -> 2 | K24: =MINUTE(B24) -> 10 | L24: =SECOND(B24) -> 0 | M24: =J24+(K24/60)+(L24/3600) -> 2.1666667 | N24: =M24-$M$11 -> 2 | O24: =($G$42-$G$13)/($N$42-$N$12)/60 -> 0.038440678 | P24: =O24*(N24-N23)*60 -> 0.38440678 | Q24: =Q23+P24 -> 6.6584746
B25: 0.097222222 | C25: 601 | F25: 0.81 | G25: =G24+F25 -> 7.29 | H25: =F25/10 -> 0.081 | J25: =HOUR(B25) -> 2 | K25: =MINUTE(B25) -> 20 | L25: =SECOND(B25) -> 0 | M25: =J25+(K25/60)+(L25/3600) -> 2.3333333 | N25: =M25-$M$11 -> 2.1666667 | O25: =($G$42-$G$13)/($N$42-$N$12)/60 -> 0.038440678 | P25: =O25*(N25-N24)*60 -> 0.38440678 | Q25: =Q24+P25 -> 7.0428814
B26: 0.10416667 | C26: 629 | F26: 0 | G26: =G25+F26 -> 7.29 | H26: =F26/10 -> 0 | J26: =HOUR(B26) -> 2 | K26: =MINUTE(B26) -> 30 | L26: =SECOND(B26) -> 0 | M26: =J26+(K26/60)+(L26/3600) -> 2.5 | N26: =M26-$M$11 -> 2.3333333 | O26: =($G$42-$G$13)/($N$42-$N$12)/60 -> 0.038440678 | P26: =O26*(N26-N25)*60 -> 0.38440678 | Q26: =Q25+P26 -> 7.4272881
B27: 0.11111111 | C27: 655 | F27: 0 | G27: =G26+F27 -> 7.29 | H27: =F27/10 -> 0 | J27: =HOUR(B27) -> 2 | K27: =MINUTE(B27) -> 40 | L27: =SECOND(B27) -> 0 | M27: =J27+(K27/60)+(L27/3600) -> 2.6666667 | N27: =M27-$M$11 -> 2.5 | O27: =($G$42-$G$13)/($N$42-$N$12)/60 -> 0.038440678 | P27: =O27*(N27-N26)*60 -> 0.38440678 | Q27: =Q26+P27 -> 7.8116949
B28: 0.11805556 | C28: 695 | F28: 0 | G28: =G27+F28 -> 7.29 | H28: =F28/10 -> 0 | J28: =HOUR(B28) -> 2 | K28: =MINUTE(B28) -> 50 | L28: =SECOND(B28) -> 0 | M28: =J28+(K28/60)+(L28/3600) -> 2.8333333 | N28: =M28-$M$11 -> 2.6666667 | O28: =($G$42-$G$13)/($N$42-$N$12)/60 -> 0.038440678 | P28: =O28*(N28-N27)*60 -> 0.38440678 | Q28: =Q27+P28 -> 8.1961017
B29: 0.125 | C29: 712 | F29: 0.81 | G29: =G28+F29 -> 8.1 | H29: =F29/10 -> 0.081 | J29: =HOUR(B29) -> 3 | K29: =MINUTE(B29) -> 0 | L29: =SECOND(B29) -> 0 | M29: =J29+(K29/60)+(L29/3600) -> 3 | N29: =M29-$M$11 -> 2.8333333 | O29: =($G$42-$G$13)/($N$42-$N$12)/60 -> 0.038440678 | P29: =O29*(N29-N28)*60 -> 0.38440678 | Q29: =Q28+P29 -> 8.5805085
B30: 0.13194444 | C30: 765 | F30: 0 | G30: =G29+F30 -> 8.1 | H30: =F30/10 -> 0 | J30: =HOUR(B30) -> 3 | K30: =MINUTE(B30) -> 10 | L30: =SECOND(B30) -> 0 | M30: =J30+(K30/60)+(L30/3600) -> 3.1666667 | N30: =M30-$M$11 -> 3 | O30: =($G$42-$G$13)/($N$42-$N$12)/60 -> 0.038440678 | P30: =O30*(N30-N29)*60 -> 0.38440678 | Q30: =Q29+P30 -> 8.9649153
B31: 0.13888889 | C31: 848 | F31: 0.81 | G31: =G30+F31 -> 8.91 | H31: =F31/10 -> 0.081 | J31: =HOUR(B31) -> 3 | K31: =MINUTE(B31) -> 20 | L31: =SECOND(B31) -> 0 | M31: =J31+(K31/60)+(L31/3600) -> 3.3333333 | N31: =M31-$M$11 -> 3.1666667 | O31: =($G$42-$G$13)/($N$42-$N$12)/60 -> 0.038440678 | P31: =O31*(N31-N30)*60 -> 0.38440678 | Q31: =Q30+P31 -> 9.349322
B32: 0.14583333 | C32: 949 | F32: 0.81 | G32: =G31+F32 -> 9.72 | H32: =F32/10 -> 0.081 | J32: =HOUR(B32) -> 3 | K32: =MINUTE(B32) -> 30 | L32: =SECOND(B32) -> 0 | M32: =J32+(K32/60)+(L32/3600) -> 3.5 | N32: =M32-$M$11 -> 3.3333333 | O32: =($G$42-$G$13)/($N$42-$N$12)/60 -> 0.038440678 | P32: =O32*(N32-N31)*60 -> 0.38440678 | Q32: =Q31+P32 -> 9.7337288
B33: 0.15277778 | C33: 949 | F33: 0 | G33: =G32+F33 -> 9.72 | H33: =F33/10 -> 0 | I33: Extra 5cm push down (Total stoke length 60cm) | J33: =HOUR(B33) -> 3 | K33: =MINUTE(B33) -> 40 | L33: =SECOND(B33) -> 0 | M33: =J33+(K33/60)+(L33/3600) -> 3.6666667 | N33: =M33-$M$11 -> 3.5 | O33: =($G$42-$G$13)/($N$42-$N$12)/60 -> 0.038440678 | P33: =O33*(N33-N32)*60 -> 0.38440678 | Q33: =Q32+P33 -> 10.118136
B34: 0.15972222 | C34: 996 | F34: 0.81 | G34: =G33+F34 -> 10.53 | H34: =F34/10 -> 0.081 | J34: =HOUR(B34) -> 3 | K34: =MINUTE(B34) -> 50 | L34: =SECOND(B34) -> 0 | M34: =J34+(K34/60)+(L34/3600) -> 3.8333333 | N34: =M34-$M$11 -> 3.6666667 | O34: =($G$42-$G$13)/($N$42-$N$12)/60 -> 0.038440678 | P34: =O34*(N34-N33)*60 -> 0.38440678 | Q34: =Q33+P34 -> 10.502542
B35: 0.16666667 | C35: 1126 | F35: 0 | G35: =G34+F35 -> 10.53 | H35: =F35/10 -> 0 | J35: =HOUR(B35) -> 4 | K35: =MINUTE(B35) -> 0 | L35: =SECOND(B35) -> 0 | M35: =J35+(K35/60)+(L35/3600) -> 4 | N35: =M35-$M$11 -> 3.8333333 | O35: =($G$42-$G$13)/($N$42-$N$12)/60 -> 0.038440678 | P35: =O35*(N35-N34)*60 -> 0.38440678 | Q35: =Q34+P35 -> 10.886949
B36: 0.17361111 | C36: 1141 | F36: 1.62 | G36: =G35+F36 -> 12.15 | H36: =F36/10 -> 0.162 | J36: =HOUR(B36) -> 4 | K36: =MINUTE(B36) -> 10 | L36: =SECOND(B36) -> 0 | M36: =J36+(K36/60)+(L36/3600) -> 4.1666667 | N36: =M36-$M$11 -> 4 | O36: =($G$42-$G$13)/($N$42-$N$12)/60 -> 0.038440678 | P36: =O36*(N36-N35)*60 -> 0.38440678 | Q36: =Q35+P36 -> 11.271356
B37: 0.18055556 | C37: 1197 | F37: 0 | G37: =G36+F37 -> 12.15 | H37: =F37/10 -> 0 | J37: =HOUR(B37) -> 4 | K37: =MINUTE(B37) -> 20 | L37: =SECOND(B37) -> 0 | M37: =J37+(K37/60)+(L37/3600) -> 4.3333333 | N37: =M37-$M$11 -> 4.1666667 | O37: =($G$42-$G$13)/($N$42-$N$12)/60 -> 0.038440678 | P37: =O37*(N37-N36)*60 -> 0.38440678 | Q37: =Q36+P37 -> 11.655763
B38: 0.1875 | C38: 1249 | F38: 0 | G38: =G37+F38 -> 12.15 | H38: =F38/10 -> 0 | J38: =HOUR(B38) -> 4 | K38: =MINUTE(B38) -> 30 | L38: =SECOND(B38) -> 0 | M38: =J38+(K38/60)+(L38/3600) -> 4.5 | N38: =M38-$M$11 -> 4.3333333 | O38: =($G$42-$G$13)/($N$42-$N$12)/60 -> 0.038440678 | P38: =O38*(N38-N37)*60 -> 0.38440678 | Q38: =Q37+P38 -> 12.040169
B39: 0.19444444 | C39: 1305 | F39: 0.81 | G39: =G38+F39 -> 12.96 | H39: =F39/10 -> 0.081 | J39: =HOUR(B39) -> 4 | K39: =MINUTE(B39) -> 40 | L39: =SECOND(B39) -> 0 | M39: =J39+(K39/60)+(L39/3600) -> 4.6666667 | N39: =M39-$M$11 -> 4.5 | O39: =($G$42-$G$13)/($N$42-$N$12)/60 -> 0.038440678 | P39: =O39*(N39-N38)*60 -> 0.38440678 | Q39: =Q38+P39 -> 12.424576
B40: 0.20138889 | C40: 1328 | F40: 0 | G40: =G39+F40 -> 12.96 | H40: =F40/10 -> 0 | J40: =HOUR(B40) -> 4 | K40: =MINUTE(B40) -> 50 | L40: =SECOND(B40) -> 0 | M40: =J40+(K40/60)+(L40/3600) -> 4.8333333 | N40: =M40-$M$11 -> 4.6666667 | O40: =($G$42-$G$13)/($N$42-$N$12)/60 -> 0.038440678 | P40: =O40*(N40-N39)*60 -> 0.38440678 | Q40: =Q39+P40 -> 12.808983
...

Sheet Rate_Schedule
A1: Flow Period | B1: End_Time | C1: FlowRate
A2: 0 | B2: 0 | C2: =VLOOKUP(B2,Injection_Note!$N$11:$O$80,2,0)*9.06 -> 0
A3: 1 | B3: 0.16666667 | C3: =VLOOKUP(B3,Injection_Note!$N$11:$O$80,2,0)*9.06 -> 2.20158
A4: 2 | B4: 5 | C4: =VLOOKUP(B4,Injection_Note!$N$11:$O$80,2,0)*9.06 -> 0.34827254
A5: 3 | B5: 9.0594444 | C5: =VLOOKUP(B5,Injection_Note!$N$11:$O$80,2,0)*9.06 -> 0.550395

Sheet Injection_Schedule
A1: Hrs | B1: Rate_Actual_BPD | C1: Rate_Average_LPM | D1: Rate_Average_BPD
A2: 0 | B2: 0 | C2: 0 | D2: =C2*9.06 -> 0
A3: 0.083333333 | B3: =Injection_Note!H12*9.06 -> 2.93544 | C3: 0.243 | D3: =C3*9.06 -> 2.20158
A4: 0.16666667 | B4: =Injection_Note!H13*9.06 -> 1.46772 | C4: 0.243 | D4: =C4*9.06 -> 2.20158
A5: 0.33333333 | B5: =Injection_Note!H14*9.06 -> 0 | C5: 0.038440678 | D5: =C5*9.06 -> 0.34827254
A6: 0.5 | B6: =Injection_Note!H15*9.06 -> 0 | C6: 0.038440678 | D6: =C6*9.06 -> 0.34827254
A7: 0.66666667 | B7: =Injection_Note!H16*9.06 -> 0.73386 | C7: 0.038440678 | D7: =C7*9.06 -> 0.34827254
A8: 0.83333333 | B8: =Injection_Note!H17*9.06 -> 0 | C8: 0.038440678 | D8: =C8*9.06 -> 0.34827254
A9: 1 | B9: =Injection_Note!H18*9.06 -> 0.73386 | C9: 0.038440678 | D9: =C9*9.06 -> 0.34827254
A10: 1.1666667 | B10: =Injection_Note!H19*9.06 -> 0.73386 | C10: 0.038440678 | D10: =C10*9.06 -> 0.34827254
A11: 1.3333333 | B11: =Injection_Note!H20*9.06 -> 0 | C11: 0.038440678 | D11: =C11*9.06 -> 0.34827254
A12: 1.5 | B12: =Injection_Note!H21*9.06 -> 0 | C12: 0.038440678 | D12: =C12*9.06 -> 0.34827254
A13: 1.6666667 | B13: =Injection_Note!H22*9.06 -> 0.73386 | C13: 0.038440678 | D13: =C13*9.06 -> 0.34827254
A14: 1.8333333 | B14: =Injection_Note!H23*9.06 -> 0.73386 | C14: 0.038440678 | D14: =C14*9.06 -> 0.34827254
... A58: 9.0594444 | B58: =Injection_Note!H67*9.06 -> 0 | C58: 0.06075 | D58: =C58*9.06 -> 0.550395

Sheet Rate_Schedule (2)
A1: Flow Period | B1: End_Time | C1: FlowRate
A2: 0 | B2: 0 | C2: =VLOOKUP(B2,Injection_Note!$N$11:$O$80,2,0)*9.06 -> 0
A3: 1 | B3: 1.1666667 | C3: =VLOOKUP(B3,Injection_Note!$N$11:$O$80,2,0)*9.06 -> 0.34827254
A4: 2 | B4: 1.6666667 | C4: =VLOOKUP(B4,Injection_Note!$N$11:$O$80,2,0)*9.06 -> #N/A
A5: 3 | B5: =Injection_Note!N26 -> 2.3333333 | C5: =VLOOKUP(B5,Injection_Note!$N$11:$O$80,2,0)*9.06 -> 0.34827254
A6: 4 | B6: =Injection_Note!N33 -> 3.5 | C6: =VLOOKUP(B6,Injection_Note!$N$11:$O$80,2,0)*9.06 -> 0.34827254 | H6: =C3*48.90815568 -> 17.033368
A7: 7 | B7: =Injection_Note!N58 -> 7.6666667 | C7: =VLOOKUP(B7,Injection_Note!$N$11:$O$80,2,0)*9.06 -> 0.550395
A8: 6 | B8: =Injection_Note!N64 -> 8.6666667 | C8: =VLOOKUP(B8,Injection_Note!$N$11:$O$80,2,0)*9.06 -> 0.550395
A9: 7 | B9: =Injection_Note!N68 -> 0 | C9: =VLOOKUP(B9,Injection_Note!$N$11:$O$80,2,0)*9.06 -> 0
A10: 8 | B10: =Injection_Note!N80 -> 0 | C10: =VLOOKUP(B10,Injection_Note!$N$11:$O$80,2,0)*9.06 -> 0
